Workbook

Sheet README
A1: SUPPLY CHAIN CONTROL TOWER
A2: Test Data Pack
A4: Purpose | B4: End-to-end test data + scenarios for every feature in the Control Tower. Use the persona table to log in, the BOM CSVs to populate projects, the suppliers list as reference, and the scenarios sheet as a click-by-click QA script.
A5: Live environments | B5: Local: https://localhost/ · Fly: https://scm-towerx.fly.dev/
A6: How to use | B6: 1. Open the 'Personas' sheet — pick any user_id to sign in. 2. Open the 'Test Scenarios' sheet — work through P1 first. 3. To populate a project's BOM, use the matching 'bom-<tenant>-<project>.csv' file via the project's BOM tab → CSV upload. 4. To exercise edge cases + watch completion respond, see the 'Edge / Status CSVs' sheet (bom-edge-* and bom-status-mix-*). 5. The 'Suppliers' and 'BOM Library' sheets are reference data for manual entry / API calls. 6. The 'API Reference' sheet documents every endpoint to hit directly with curl / Postman.
A7: Tenants | B7: arcforge (Power Systems EPC) · helios (Offshore Engineering) · northwind (Heavy Engineering). All data is tenant-scoped — cross-tenant reads return 404.
A8: Auth | B8: POST /api/auth/login with { "user_id": "<persona>" } returns a JWT. Send as Authorization: Bearer <token>. 8h TTL. JWT secret is set via the JWT_SECRET env var in prod.

Sheet Personas
A1: AUTH
A2: Personas — pick any user_id to sign in
A4: user_id | B4: Display name | C4: Email | D4: Tenant | E4: Role | F4: What this persona can do
A5: arcforge-admin-01 | B5: Admin | C5: admin@arcforge.com | D5: Arcforge Engineering | E5: admin | F5: All read + write across modules + tenant switch (admin only).
A6: arcforge-head-01 | B6: Procurement Head | C6: head@arcforge.com | D6: Arcforge Engineering | E6: procurement_head | F6: Read all + manage PR/RFQ/Award/PO + decide approvals.
A7: arcforge-buyer-01 | B7: Buyer | C7: buyer@arcforge.com | D7: Arcforge Engineering | E7: buyer | F7: Read all + create PR, RFQ, Quote. Cannot award POs over threshold.
A8: arcforge-expeditor-01 | B8: Lead Expeditor | C8: expeditor@arcforge.com | D8: Arcforge Engineering | E8: expeditor | F8: Read all + create follow-up emails + shipment events.
A9: arcforge-viewer-01 | B9: Project Controls Viewer | C9: viewer@arcforge.com | D9: Arcforge Engineering | E9: viewer | F9: Read-only access to every page.
A10: helios-admin-01 | B10: Admin | C10: admin@helios-offshore.com | D10: Helios Offshore | E10: admin | F10: All read + write across modules + tenant switch (admin only).
A11: helios-head-01 | B11: Procurement Head | C11: head@helios-offshore.com | D11: Helios Offshore | E11: procurement_head | F11: Read all + manage PR/RFQ/Award/PO + decide approvals.
A12: helios-buyer-01 | B12: Buyer | C12: buyer@helios-offshore.com | D12: Helios Offshore | E12: buyer | F12: Read all + create PR, RFQ, Quote. Cannot award POs over threshold.
A13: helios-expeditor-01 | B13: Lead Expeditor | C13: expeditor@helios-offshore.com | D13: Helios Offshore | E13: expeditor | F13: Read all + create follow-up emails + shipment events.
A14: helios-viewer-01 | B14: Project Controls Viewer | C14: viewer@helios-offshore.com | D14: Helios Offshore | E14: viewer | F14: Read-only access to every page.
A15: northwind-admin-01 | B15: Admin | C15: admin@northwind.co | D15: Northwind Heavy Engineering | E15: admin | F15: All read + write across modules + tenant switch (admin only).
... A19: northwind-viewer-01 | B19: Project Controls Viewer | C19: viewer@northwind.co | D19: Northwind Heavy Engineering | E19: viewer | F19: Read-only access to every page.

Sheet Projects
A1: PORTFOLIO
A2: Projects — 4 per tenant, 1 in-execution each
A4: Tenant | B4: project_id | C4: Name | D4: Client | E4: Site | F4: Sector | G4: Expected completion (today) | H4: Seeded BOM lines
A5: arcforge | B5: PRJ-RB-660 | C5: Riverbank 2x660 MW Power Plant | D5: Arcforge Power | E5: Riverbank, Gujarat | F5: Power EPC | G5: 0% | H5: 8
A6: arcforge | B6: PRJ-AF-CCGT | C6: Tanjore Combined-Cycle Gas Plant 750 MW | D6: Arcforge Power | E6: Tanjore, Tamil Nadu | F6: Power EPC | G6: 0% | H6: 5
A7: arcforge | B7: PRJ-AF-SUB | C7: Sundarpur 765 kV Substation Upgrade | D7: Arcforge Grid | E7: Sundarpur, Madhya Pradesh | F7: Transmission EPC | G7: 0% | H7: 5
A8: arcforge | B8: PRJ-AF-MERIDIAN | C8: Meridian 2x350 MW CCGT — Unit 1 Execution | D8: Arcforge Power | E8: Meridian, Andhra Pradesh | F8: Power EPC | G8: ~56% (in-flight) | H8: 9
A9: helios | B9: PRJ-NS-OSS | C9: North Sea Offshore Substation | D9: Helios Offshore Operations | E9: Aberdeen, UK | F9: Offshore Engineering | G9: 0% | H9: 4
A10: helios | B10: PRJ-HE-WIND | C10: Dogger Bank Offshore Wind 480 MW | D10: Helios Renewables | E10: Dogger Bank, North Sea | F10: Offshore Wind EPC | G10: 0% | H10: 5
A11: helios | B11: PRJ-HE-FPSO | C11: Hawthorn FPSO Topsides | D11: Helios Upstream | E11: West of Shetland | F11: Offshore Oil & Gas EPC | G11: 0% | H11: 5
A12: helios | B12: PRJ-HE-VALHALL | C12: Valhall Bravo Platform Tie-In | D12: Helios Upstream | E12: Valhall Field, North Sea | F12: Offshore Oil & Gas EPC | G12: ~56% (in-flight) | H12: 9
A13: northwind | B13: HYD-MAHADEV-220 | C13: Mahadev Hydro 220 MW (2x110) | D13: Northern Hills Power Corporation | E13: Sutlej Basin, Himachal Pradesh | F13: Hydropower EPC | G13: ~17% | H13: 70
A14: northwind | B14: PRJ-NW-STEEL | C14: Polaris Steel Rolling Mill Modernization | D14: Polaris Steel | E14: Jamshedpur, Jharkhand | F14: Heavy Industry EPC | G14: 0% | H14: 5
A15: northwind | B15: PRJ-NW-CEMENT | C15: Granite Ridge Cement Line 2 | D15: Granite Ridge Cement | E15: Chandrapur, Maharashtra | F15: Heavy Industry EPC | G15: 0% | H15: 5
A16: northwind | B16: PRJ-NW-KAVI | C16: Kavi Hydro Unit 3 Major Overhaul | D16: Northern Hills Power Corporation | E16: Kavi, Himachal Pradesh | F16: Hydropower EPC | G16: ~53% (in-flight) | H16: 9

Sheet BOM-Arcforge
A1: BOM
A2: BOM-Arcforge — uploadable to PRJ-RB-660
A4: project_id | B4: code | C4: description | D4: category | E4: quantity | F4: uom | G4: unit_cost_usd | H4: supplier_name | I4: spec_doc_id | J4: drawing_id | K4: long_lead_days | L4: planned_need_date | M4: milestone_code | N4: status
A5: PRJ-RB-660 | B5: BFP-660-B | C5: Boiler feed pump set B | D5: Rotating equipment | E5: 2 | F5: EA | G5: 920000 | H5: Helios Cast & Forge | I5: SPEC-RB-001 | J5: DRG-RB-001 | K5: 240 | L5: 2026-11-27 | M5: M3 | N5: planned
A6: PRJ-RB-660 | B6: DEAERATOR-660 | C6: Deaerator + storage tank | D6: Process | E6: 1 | F6: EA | G6: 380000 | H6: Kerala Forge Works | I6: SPEC-RB-001 | K6: 180 | L6: 2026-10-28 | M6: M3 | N6: planned
A7: PRJ-RB-660 | B7: CONDENSER-AC | C7: Air-cooled condenser bank | D7: Process | E7: 8 | F7: EA | G7: 220000 | K7: 270 | L7: 2026-12-17 | M7: M4 | N7: spec_missing
A8: PRJ-RB-660 | B8: HRSG-MODULE | C8: HRSG pressure module | D8: Heat recovery | E8: 4 | F8: EA | G8: 1100000 | H8: Helios Cast & Forge | I8: SPEC-RB-001 | K8: 300 | L8: 2026-12-27 | M8: M3 | N8: planned
A9: PRJ-RB-660 | B9: ECONOMIZER-COIL | C9: Economizer coil bundle | D9: Heat recovery | E9: 4 | F9: EA | G9: 180000 | H9: Helios Cast & Forge | K9: 210 | L9: 2026-10-28 | M9: M3 | N9: spec_missing
A10: PRJ-RB-660 | B10: DESH-PIPING-CR | C10: Desuperheater piping chrome-moly | D10: Piping | E10: 320 | F10: M | G10: 1200 | H10: Copperline Metals | K10: 90 | L10: 2026-09-28 | M10: M3 | N10: spec_missing
A11: PRJ-RB-660 | B11: VALVE-24-A105 | C11: 24-inch forged gate valve | D11: Forged valves | E11: 12 | F11: EA | G11: 6800 | H11: Kerala Forge Works | I11: SPEC-RB-002 | K11: 120 | L11: 2026-09-08 | M11: M3 | N11: planned
A12: PRJ-RB-660 | B12: RELIEF-VALVE | C12: Steam relief valve assembly | D12: Forged valves | E12: 24 | F12: EA | G12: 2400 | H12: Kerala Forge Works | K12: 90 | L12: 2026-09-18 | M12: M3 | N12: spec_missing
A13: PRJ-RB-660 | B13: ACTUATOR-PNEU | C13: Pneumatic valve actuator | D13: Automation | E13: 36 | F13: EA | G13: 1800 | H13: Mitsuba Automation | K13: 75 | L13: 2026-08-24 | M13: M2 | N13: spec_missing
A14: PRJ-RB-660 | B14: SOOT-BLOWER | C14: Wall-tube soot blower set | D14: Process | E14: 16 | F14: EA | G14: 14000 | K14: 150 | L14: 2026-11-27 | M14: M3 | N14: spec_missing
A15: PRJ-RB-660 | B15: HV-SWITCHGEAR-11 | C15: 11 kV switchgear panel | D15: Electrical | E15: 6 | F15: EA | G15: 95000 | H15: BluePeak Controls | I15: SPEC-RB-001 | K15: 180 | L15: 2026-11-07 | M15: M3 | N15: planned
A16: PRJ-RB-660 | B16: CT-MV-630 | C16: MV current transformer 630A | D16: Electrical | E16: 24 | F16: EA | G16: 4200 | H16: BluePeak Controls | K16: 90 | L16: 2026-09-18 | M16: M3 | N16: spec_missing
A17: PRJ-RB-660 | B17: MOTOR-IM-3300 | C17: 3.3 kV induction motor 4 MW | D17: Rotating equipment | E17: 6 | F17: EA | G17: 165000 | H17: Helios Cast & Forge | K17: 180 | L17: 2026-10-28 | M17: M3 | N17: spec_missing
A18: PRJ-RB-660 | B18: PLC-S7-CPU | C18: PLC CPU module 1500 series | D18: Automation | E18: 8 | F18: EA | G18: 8400 | H18: BluePeak Controls | K18: 60 | L18: 2026-08-19 | M18: M2 | N18: spec_missing
A19: PRJ-RB-660 | B19: CABLE-MV-XLPE | C19: 33 kV XLPE single-core cable | D19: Cables | E19: 18 | F19: KM | G19: 92000 | H19: Copperline Metals | K19: 75 | L19: 2026-09-18 | M19: M3 | N19: spec_missing
A20: PRJ-RB-660 | B20: CABLE-CONTROL | C20: Multipair instrumentation cable | D20: Cables | E20: 42 | F20: KM | G20: 6800 | H20: Copperline Metals | K20: 60 | L20: 2026-09-08 | M20: M3 | N20: spec_missing
A21: PRJ-RB-660 | B21: CONDUIT-GAL | C21: Hot-dip galvanized conduit | D21: Electrical | E21: 8400 | F21: M | G21: 22 | H21: Delhi Metals Co | K21: 30 | L21: 2026-07-30 | M21: M2 | N21: spec_missing
A22: PRJ-RB-660 | B22: RACEWAY-CABLE | C22: Cable raceway galvanized | D22: Electrical | E22: 2200 | F22: M | G22: 86 | H22: Delhi Metals Co | K22: 30 | L22: 2026-07-30 | M22: M2 | N22: spec_missing
A23: PRJ-RB-660 | B23: INSTR-PRES | C23: Pressure transmitter HART | D23: Instrumentation | E23: 240 | F23: EA | G23: 1100 | H23: Mitsuba Automation | K23: 75 | L23: 2026-08-19 | M23: M2 | N23: spec_missing
A24: PRJ-RB-660 | B24: INSTR-TEMP-RTD | C24: RTD temperature sensor | D24: Instrumentation | E24: 380 | F24: EA | G24: 240 | H24: Mitsuba Automation | K24: 60 | L24: 2026-08-14 | M24: M2 | N24: spec_missing
A25: PRJ-RB-660 | B25: INSTR-FLOW-VTX | C25: Vortex flow meter | D25: Instrumentation | E25: 64 | F25: EA | G25: 4800 | H25: Mitsuba Automation | K25: 75 | L25: 2026-08-24 | M25: M2 | N25: spec_missing
A26: PRJ-RB-660 | B26: BALL-VALVE-2 | C26: 2"-150 ball valve carbon | D26: Forged valves | E26: 480 | F26: EA | G26: 320 | H26: Kerala Forge Works | K26: 60 | L26: 2026-08-29 | M26: M2 | N26: spec_missing
A27: PRJ-RB-660 | B27: PSV-150-HF | C27: Pilot-operated PSV | D27: Forged valves | E27: 36 | F27: EA | G27: 4800 | K27: 120 | L27: 2026-09-28 | M27: M3 | N27: spec_missing
A28: PRJ-RB-660 | B28: UPS-CRITICAL | C28: 100 kVA critical load UPS | D28: Electrical | E28: 4 | F28: EA | G28: 78000 | H28: BluePeak Controls | K28: 90 | L28: 2026-09-18 | M28: M3 | N28: spec_missing
A29: PRJ-RB-660 | B29: BATTERY-VRLA | C29: VRLA battery bank 220V | D29: Electrical | E29: 6 | F29: EA | G29: 14000 | H29: BluePeak Controls | K29: 60 | L29: 2026-08-29 | M29: M3 | N29: spec_missing
A30: PRJ-RB-660 | B30: FIRE-DELUGE | C30: Deluge valve fire-water | D30: Fire | E30: 18 | F30: EA | G30: 6200 | K30: 90 | L30: 2026-09-28 | M30: M3 | N30: spec_missing
A31: PRJ-RB-660 | B31: FIRE-CO2-CYL | C31: CO2 cylinder bank | D31: Fire | E31: 24 | F31: EA | G31: 980 | K31: 45 | L31: 2026-08-29 | M31: M3 | N31: spec_missing
A32: PRJ-RB-660 | B32: PIPING-CS-A106 | C32: A106-B carbon steel pipe | D32: Piping | E32: 1800 | F32: M | G32: 320 | H32: Copperline Metals | K32: 75 | L32: 2026-09-18 | M32: M3 | N32: spec_missing
A33: PRJ-RB-660 | B33: PIPING-SS-316 | C33: SS316L stainless pipe | D33: Piping | E33: 420 | F33: M | G33: 980 | H33: Copperline Metals | K33: 90 | L33: 2026-09-18 | M33: M3 | N33: spec_missing
A34: PRJ-RB-660 | B34: CRANE-EOT-50 | C34: EOT crane 50T | D34: Crane / lifting | E34: 2 | F34: EA | G34: 285000 | K34: 240 | L34: 2026-12-17 | M34: M4 | N34: spec_missing
A35: PRJ-RB-660 | B35: HVAC-AHU-30K | C35: AHU 30,000 CFM | D35: HVAC | E35: 6 | F35: EA | G35: 64000 | K35: 120 | L35: 2026-10-28 | M35: M4 | N35: spec_missing
A36: PRJ-RB-660 | B36: CW-PUMP-VS | C36: Cooling water vertical pump | D36: Cooling | E36: 4 | F36: EA | G36: 240000 | H36: Helios Cast & Forge | K36: 180 | L36: 2026-10-28 | M36: M3 | N36: spec_missing
A37: PRJ-RB-660 | B37: OIL-LUBE-SKID | C37: Lube oil skid 200 GPM | D37: Lubrication | E37: 2 | F37: EA | G37: 96000 | K37: 150 | L37: 2026-11-07 | M37: M3 | N37: spec_missing
A38: PRJ-RB-660 | B38: STRUCT-BEAM | C38: Structural beam W-section | D38: Structural | E38: 580 | F38: T | G38: 1850 | K38: 60 | L38: 2026-08-29 | M38: M3 | N38: spec_missing
A39: PRJ-RB-660 | B39: REBAR-BUNDLE | C39: Rebar #8 bundle | D39: Civil | E39: 1200 | F39: T | G39: 720 | K39: 30 | L39: 2026-07-30 | M39: M2 | N39: spec_missing
A40: PRJ-RB-660 | B40: EARTH-CABLE-CU | C40: Copper earthing cable | D40: Electrical | E40: 6800 | F40: M | G40: 28 | H40: Copperline Metals | K40: 45 | L40: 2026-08-29 | M40: M2 | N40: spec_missing
A41: PRJ-RB-660 | B41: LIGHTING-FIX-LED | C41: LED industrial light fixture | D41: Electrical | E41: 480 | F41: EA | G41: 280 | H41: Delhi Metals Co | K41: 30 | L41: 2026-07-30 | M41: M2 | N41: spec_missing
...

Sheet BOM-Helios
A1: BOM
A2: BOM-Helios — uploadable to PRJ-NS-OSS
A4: project_id | B4: code | C4: description | D4: category | E4: quantity | F4: uom | G4: unit_cost_usd | H4: supplier_name | I4: spec_doc_id | J4: drawing_id | K4: long_lead_days | L4: planned_need_date | M4: milestone_code | N4: status
A5: PRJ-NS-OSS | B5: GIS-66-BAY | C5: GIS 66 kV bay extension | D5: Electrical | E5: 4 | F5: EA | G5: 880000 | H5: BluePeak Controls | I5: SPEC-NS-001 | J5: DRG-NS-001 | K5: 280 | L5: 2026-11-27 | M5: M3 | N5: planned
A6: PRJ-NS-OSS | B6: XFMR-PWR-220 | C6: Power transformer 220 MVA | D6: Electrical | E6: 2 | F6: EA | G6: 2400000 | K6: 380 | L6: 2026-12-17 | M6: M3 | N6: spec_missing
A7: PRJ-NS-OSS | B7: REACTOR-SH | C7: Shunt reactor 200 MVAr | D7: Electrical | E7: 2 | F7: EA | G7: 920000 | H7: BluePeak Controls | K7: 300 | L7: 2026-12-17 | M7: M3 | N7: spec_missing
A8: PRJ-NS-OSS | B8: UMBILICAL-DYN | C8: Dynamic umbilical cable | D8: Subsea cables | E8: 12 | F8: KM | G8: 480000 | H8: NorthCable Subsea | I8: SPEC-NS-001 | K8: 360 | L8: 2027-01-06 | M8: M3 | N8: planned
A9: PRJ-NS-OSS | B9: J-TUBE-CRA | C9: J-tube CRA lined | D9: Tubing | E9: 12 | F9: EA | G9: 95000 | H9: Copperline Metals | K9: 90 | L9: 2026-10-18 | M9: M3 | N9: spec_missing
A10: PRJ-NS-OSS | B10: BUSHING-66KV | C10: 66 kV transformer bushing | D10: Electrical | E10: 12 | F10: EA | G10: 38000 | H10: BluePeak Controls | K10: 180 | L10: 2026-11-07 | M10: M3 | N10: spec_missing
A11: PRJ-NS-OSS | B11: SURGE-ARRESTER | C11: Surge arrester 66 kV | D11: Electrical | E11: 18 | F11: EA | G11: 8400 | H11: BluePeak Controls | K11: 90 | L11: 2026-09-28 | M11: M3 | N11: spec_missing
A12: PRJ-NS-OSS | B12: CABLE-LV-SHIP | C12: LV shipboard armoured cable | D12: Cables | E12: 32 | F12: KM | G12: 64000 | H12: NorthCable Subsea | K12: 75 | L12: 2026-09-28 | M12: M3 | N12: spec_missing
A13: PRJ-NS-OSS | B13: DECK-PLATING | C13: Deck plating EH36 grade | D13: Offshore structural | E13: 380 | F13: T | G13: 2900 | H13: Aberdeen Steel Fab | K13: 120 | L13: 2026-10-28 | M13: M2 | N13: spec_missing
A14: PRJ-NS-OSS | B14: PILE-SLEEVE | C14: Pile sleeve fabrication | D14: Offshore structural | E14: 8 | F14: EA | G14: 240000 | H14: Aberdeen Steel Fab | K14: 180 | L14: 2026-12-17 | M14: M3 | N14: spec_missing
A15: PRJ-NS-OSS | B15: PADEYE-MAIN | C15: Main lifting padeye | D15: Offshore structural | E15: 16 | F15: EA | G15: 18000 | H15: Aberdeen Steel Fab | K15: 90 | L15: 2026-09-28 | M15: M2 | N15: spec_missing
A16: PRJ-NS-OSS | B16: COATING-IZ | C16: Inorganic zinc primer | D16: Marine epoxy | E16: 1800 | F16: L | G16: 22 | H16: Coastline Marine Coatings | K16: 45 | L16: 2026-08-14 | M16: M2 | N16: spec_missing
A17: PRJ-NS-OSS | B17: COATING-EPOXY | C17: Epoxy mid coat | D17: Marine epoxy | E17: 1200 | F17: L | G17: 28 | H17: Coastline Marine Coatings | K17: 45 | L17: 2026-08-14 | M17: M2 | N17: spec_missing
A18: PRJ-NS-OSS | B18: ROV-PANEL | C18: ROV interface panel | D18: ROV connectors | E18: 6 | F18: EA | G18: 64000 | H18: DeepDive ROV Systems | K18: 120 | L18: 2026-10-28 | M18: M3 | N18: spec_missing
A19: PRJ-NS-OSS | B19: BUOY-SUB | C19: Subsea distributed buoyancy | D19: ROV connectors | E19: 24 | F19: EA | G19: 8400 | H19: DeepDive ROV Systems | K19: 90 | L19: 2026-09-28 | M19: M3 | N19: spec_missing
A20: PRJ-NS-OSS | B20: FENDER-DOLPHIN | C20: Vessel fender + dolphin | D20: Marine equipment | E20: 8 | F20: EA | G20: 96000 | H20: Aberdeen Steel Fab | K20: 120 | L20: 2026-10-28 | M20: M3 | N20: spec_missing
... A22: PRJ-NS-OSS | B22: HANDRAIL-SS | C22: SS316 handrail tubular | D22: Offshore structural | E22: 2800 | F22: M | G22: 86 | H22: Copperline Metals | K22: 45 | L22: 2026-08-29 | M22: M2 | N22: spec_missing
A23: PRJ-NS-OSS | B23: LIFEBOAT-DAVIT | C23: Lifeboat davit launching system | D23: Marine equipment | E23: 4 | F23: EA | G23: 320000 | K23: 240 | L23: 2027-01-06 | M23: M3 | N23: spec_missing
A24: PRJ-NS-OSS | B24: LIFERAFT-25P | C24: 25-person life raft container | D24: Marine equipment | E24: 12 | F24: EA | G24: 18000 | K24: 60 | L24: 2026-09-28 | M24: M3 | N24: spec_missing
A25: PRJ-NS-OSS | B25: VENT-AHU-EX | C25: Ex-rated AHU | D25: HVAC | E25: 6 | F25: EA | G25: 84000 | K25: 120 | L25: 2026-10-28 | M25: M3 | N25: spec_missing
A26: PRJ-NS-OSS | B26: HVAC-DAMPER-FG | C26: Fire/gas damper | D26: HVAC | E26: 28 | F26: EA | G26: 4200 | K26: 90 | L26: 2026-09-28 | M26: M3 | N26: spec_missing
A27: PRJ-NS-OSS | B27: FW-PUMP-ELEC | C27: Electric firewater pump | D27: Fire | E27: 4 | F27: EA | G27: 240000 | K27: 180 | L27: 2026-11-07 | M27: M3 | N27: spec_missing
A28: PRJ-NS-OSS | B28: GAS-DETECT-IR | C28: IR gas detector | D28: Instrumentation | E28: 96 | F28: EA | G28: 2800 | H28: DeepDive ROV Systems | K28: 90 | L28: 2026-09-18 | M28: M3 | N28: spec_missing
A29: PRJ-NS-OSS | B29: F&G-PANEL | C29: F&G control panel | D29: Automation | E29: 4 | F29: EA | G29: 145000 | H29: BluePeak Controls | K29: 150 | L29: 2026-10-28 | M29: M3 | N29: spec_missing
A30: PRJ-NS-OSS | B30: PAGA-SYSTEM | C30: PAGA public address | D30: Automation | E30: 1 | F30: LOT | G30: 380000 | H30: BluePeak Controls | K30: 180 | L30: 2026-11-17 | M30: M3 | N30: spec_missing
A31: PRJ-NS-OSS | B31: HELI-DECK-NET | C31: Helideck perimeter safety net | D31: Offshore structural | E31: 1 | F31: LOT | G31: 95000 | H31: Aberdeen Steel Fab | K31: 90 | L31: 2026-10-18 | M31: M3 | N31: spec_missing
A32: PRJ-NS-OSS | B32: MOORING-CHAIN | C32: R4 mooring chain 95mm | D32: Mooring | E32: 1800 | F32: M | G32: 980 | K32: 270 | L32: 2026-12-17 | M32: M3 | N32: spec_missing
A33: PRJ-NS-OSS | B33: ANCHOR-DEA | C33: Drag embedment anchor | D33: Mooring | E33: 8 | F33: EA | G33: 220000 | K33: 240 | L33: 2026-12-17 | M33: M3 | N33: spec_missing
A34: PRJ-NS-OSS | B34: DP-THRUSTER | C34: Azimuth thruster 3 MW | D34: Rotating equipment | E34: 4 | F34: EA | G34: 1850000 | K34: 360 | L34: 2027-01-06 | M34: M3 | N34: spec_missing
A35: PRJ-NS-OSS | B35: CRANE-OFFSHORE | C35: Knuckle-boom crane 50T | D35: Crane / lifting | E35: 2 | F35: EA | G35: 580000 | K35: 270 | L35: 2026-12-17 | M35: M3 | N35: spec_missing
A36: PRJ-NS-OSS | B36: CONN-WET-MATE | C36: ROV wet-mate 24-pin connector | D36: ROV connectors | E36: 24 | F36: EA | G36: 5600 | H36: DeepDive ROV Systems | K36: 90 | L36: 2026-09-18 | M36: M3 | N36: spec_missing
A38: TOTAL LINES | E38: =COUNTA(B5:B36) -> 32 | G38: =SUMPRODUCT(E5:E36,G5:G36) -> 41816600

Sheet BOM-Northwind
A1: BOM
A2: BOM-Northwind — uploadable to HYD-MAHADEV-220
A4: project_id | B4: code | C4: description | D4: category | E4: quantity | F4: uom | G4: unit_cost_usd | H4: supplier_name | I4: spec_doc_id | J4: drawing_id | K4: long_lead_days | L4: planned_need_date | M4: milestone_code | N4: status
A5: HYD-MAHADEV-220 | B5: RUNNER-FRANCIS-A | C5: Francis turbine runner Unit A | D5: Hydro turbines | E5: 1 | F5: EA | G5: 2400000 | H5: Andritz Hydro | I5: SPEC-HYD-001 | J5: DRG-HYD-RUN | K5: 420 | L5: 2027-03-07 | M5: M07 | N5: planned
A6: HYD-MAHADEV-220 | B6: RUNNER-FRANCIS-B | C6: Francis turbine runner Unit B | D6: Hydro turbines | E6: 1 | F6: EA | G6: 2400000 | H6: Andritz Hydro | I6: SPEC-HYD-001 | J6: DRG-HYD-RUN | K6: 420 | L6: 2027-04-06 | M6: M08 | N6: planned
A7: HYD-MAHADEV-220 | B7: WICKET-GATE-A | C7: Wicket gate assembly Unit A | D7: Hydro turbines | E7: 24 | F7: EA | G7: 48000 | H7: Andritz Hydro | K7: 240 | L7: 2027-01-06 | M7: M07 | N7: spec_missing
A8: HYD-MAHADEV-220 | B8: WICKET-GATE-B | C8: Wicket gate assembly Unit B | D8: Hydro turbines | E8: 24 | F8: EA | G8: 48000 | H8: Andritz Hydro | K8: 240 | L8: 2027-02-05 | M8: M07 | N8: spec_missing
A9: HYD-MAHADEV-220 | B9: SPIRAL-CASE-A | C9: Spiral casing Unit A | D9: Hydro turbines | E9: 1 | F9: EA | G9: 980000 | H9: Andritz Hydro | K9: 300 | L9: 2027-01-06 | M9: M07 | N9: spec_missing
A10: HYD-MAHADEV-220 | B10: SPIRAL-CASE-B | C10: Spiral casing Unit B | D10: Hydro turbines | E10: 1 | F10: EA | G10: 980000 | H10: Andritz Hydro | K10: 300 | L10: 2027-02-05 | M10: M07 | N10: spec_missing
A11: HYD-MAHADEV-220 | B11: DRAFT-TUBE-A | C11: Draft tube fabrication Unit A | D11: Hydro turbines | E11: 1 | F11: EA | G11: 320000 | H11: Voith Industrial Services | K11: 240 | L11: 2027-01-06 | M11: M07 | N11: spec_missing
A12: HYD-MAHADEV-220 | B12: DRAFT-TUBE-B | C12: Draft tube fabrication Unit B | D12: Hydro turbines | E12: 1 | F12: EA | G12: 320000 | H12: Voith Industrial Services | K12: 240 | L12: 2027-02-05 | M12: M07 | N12: spec_missing
A13: HYD-MAHADEV-220 | B13: GEN-STATOR-A | C13: Generator stator assembly A | D13: Generators | E13: 1 | F13: EA | G13: 1850000 | H13: Bharat Heavy Electricals | I13: SPEC-HYD-002 | K13: 420 | L13: 2027-03-17 | M13: M08 | N13: planned
A14: HYD-MAHADEV-220 | B14: GEN-STATOR-B | C14: Generator stator assembly B | D14: Generators | E14: 1 | F14: EA | G14: 1850000 | H14: Bharat Heavy Electricals | I14: SPEC-HYD-002 | K14: 420 | L14: 2027-04-16 | M14: M08 | N14: planned
A15: HYD-MAHADEV-220 | B15: GEN-ROTOR-A | C15: Generator rotor + poles A | D15: Generators | E15: 1 | F15: EA | G15: 1450000 | H15: Bharat Heavy Electricals | K15: 420 | L15: 2027-03-17 | M15: M08 | N15: spec_missing
A16: HYD-MAHADEV-220 | B16: GEN-ROTOR-B | C16: Generator rotor + poles B | D16: Generators | E16: 1 | F16: EA | G16: 1450000 | H16: Bharat Heavy Electricals | K16: 420 | L16: 2027-04-16 | M16: M08 | N16: spec_missing
A17: HYD-MAHADEV-220 | B17: EXCITER-A | C17: Brushless exciter Unit A | D17: Generators | E17: 1 | F17: EA | G17: 240000 | H17: Bharat Heavy Electricals | K17: 240 | L17: 2027-03-07 | M17: M08 | N17: spec_missing
A18: HYD-MAHADEV-220 | B18: EXCITER-B | C18: Brushless exciter Unit B | D18: Generators | E18: 1 | F18: EA | G18: 240000 | H18: Bharat Heavy Electricals | K18: 240 | L18: 2027-04-06 | M18: M08 | N18: spec_missing
A19: HYD-MAHADEV-220 | B19: XFMR-GSU-160 | C19: Generator step-up transformer 160 MVA | D19: Electrical | E19: 2 | F19: EA | G19: 1100000 | K19: 360 | L19: 2027-03-27 | M19: M09 | N19: spec_missing
A20: HYD-MAHADEV-220 | B20: XFMR-AUX | C20: Auxiliary transformer 5 MVA | D20: Electrical | E20: 4 | F20: EA | G20: 145000 | H20: Bharat Heavy Electricals | K20: 180 | L20: 2026-11-27 | M20: M07 | N20: spec_missing
A21: HYD-MAHADEV-220 | B21: GIS-220-BAY | C21: 220 kV GIS bay | D21: Electrical | E21: 6 | F21: EA | G21: 1450000 | K21: 320 | L21: 2027-04-26 | M21: M10 | N21: spec_missing
A22: HYD-MAHADEV-220 | B22: GIS-66-FEEDER | C22: 66 kV GIS feeder bay | D22: Electrical | E22: 4 | F22: EA | G22: 380000 | K22: 240 | L22: 2027-03-27 | M22: M09 | N22: spec_missing
A23: HYD-MAHADEV-220 | B23: PROT-RELAY-A | C23: Generator protection relay panel | D23: Automation | E23: 2 | F23: EA | G23: 96000 | K23: 180 | L23: 2027-03-27 | M23: M09 | N23: spec_missing
A24: HYD-MAHADEV-220 | B24: GOV-DIGITAL-A | C24: Digital governor + hydraulics A | D24: Automation | E24: 1 | F24: EA | G24: 620000 | H24: Voith Industrial Services | K24: 240 | L24: 2027-03-07 | M24: M07 | N24: spec_missing
A25: HYD-MAHADEV-220 | B25: GOV-DIGITAL-B | C25: Digital governor + hydraulics B | D25: Automation | E25: 1 | F25: EA | G25: 620000 | H25: Voith Industrial Services | K25: 240 | L25: 2027-04-06 | M25: M07 | N25: spec_missing
A26: HYD-MAHADEV-220 | B26: PENSTOCK-LINER-1 | C26: Penstock liner segment 1 | D26: Penstock fabrication | E26: 6 | F26: EA | G26: 380000 | H26: Voith Industrial Services | I26: SPEC-HYD-003 | K26: 300 | L26: 2026-10-28 | M26: M06 | N26: planned
A27: HYD-MAHADEV-220 | B27: PENSTOCK-LINER-2 | C27: Penstock liner segment 2 | D27: Penstock fabrication | E27: 6 | F27: EA | G27: 380000 | H27: Voith Industrial Services | K27: 300 | L27: 2026-11-17 | M27: M06 | N27: spec_missing
A28: HYD-MAHADEV-220 | B28: PENSTOCK-RING | C28: Penstock stiffening ring | D28: Penstock fabrication | E28: 24 | F28: EA | G28: 28000 | H28: Voith Industrial Services | K28: 180 | L28: 2026-10-28 | M28: M06 | N28: spec_missing
A29: HYD-MAHADEV-220 | B29: EXP-JOINT | C29: Expansion joint bellows | D29: Piping | E29: 8 | F29: EA | G29: 38000 | K29: 150 | L29: 2026-11-27 | M29: M07 | N29: spec_missing
A30: HYD-MAHADEV-220 | B30: BUTTERFLY-3M | C30: 3 m butterfly intake valve | D30: Forged valves | E30: 2 | F30: EA | G30: 980000 | K30: 300 | L30: 2027-01-06 | M30: M07 | N30: spec_missing
A31: HYD-MAHADEV-220 | B31: GATE-RADIAL | C31: Radial gate spillway | D31: Hydro turbines | E31: 4 | F31: EA | G31: 480000 | K31: 270 | L31: 2026-11-17 | M31: M06 | N31: spec_missing
A32: HYD-MAHADEV-220 | B32: HOIST-RADIAL | C32: Spillway gate hoist | D32: Crane / lifting | E32: 4 | F32: EA | G32: 220000 | K32: 240 | L32: 2026-11-27 | M32: M06 | N32: spec_missing
A33: HYD-MAHADEV-220 | B33: EOT-CRANE-200 | C33: EOT crane 200T | D33: Crane / lifting | E33: 1 | F33: EA | G33: 480000 | K33: 300 | L33: 2027-01-06 | M33: M07 | N33: spec_missing
A34: HYD-MAHADEV-220 | B34: EOT-CRANE-50-AUX | C34: EOT crane 50T auxiliary | D34: Crane / lifting | E34: 2 | F34: EA | G34: 220000 | K34: 240 | L34: 2027-01-06 | M34: M07 | N34: spec_missing
A35: HYD-MAHADEV-220 | B35: COOLING-HEX | C35: Heat exchanger generator cooling | D35: Cooling | E35: 4 | F35: EA | G35: 86000 | K35: 180 | L35: 2027-03-07 | M35: M08 | N35: spec_missing
A36: HYD-MAHADEV-220 | B36: OIL-PURIFIER | C36: Oil purification skid | D36: Lubrication | E36: 2 | F36: EA | G36: 64000 | K36: 150 | L36: 2027-03-07 | M36: M08 | N36: spec_missing
A37: HYD-MAHADEV-220 | B37: FIRE-CO2-SYS | C37: CO2 fire suppression generator | D37: Fire | E37: 4 | F37: EA | G37: 38000 | K37: 120 | L37: 2027-03-17 | M37: M08 | N37: spec_missing
A38: HYD-MAHADEV-220 | B38: HVAC-MACH-HALL | C38: Machine hall HVAC system | D38: HVAC | E38: 1 | F38: LOT | G38: 580000 | K38: 180 | L38: 2027-03-27 | M38: M09 | N38: spec_missing
A39: HYD-MAHADEV-220 | B39: DCS-HYDRO | C39: DCS distributed control system | D39: Automation | E39: 1 | F39: LOT | G39: 1850000 | K39: 240 | L39: 2027-04-06 | M39: M09 | N39: spec_missing
A40: HYD-MAHADEV-220 | B40: INSTR-VIB | C40: Vibration monitoring system | D40: Instrumentation | E40: 12 | F40: EA | G40: 28000 | K40: 150 | L40: 2027-03-17 | M40: M08 | N40: spec_missing
... A61: HYD-MAHADEV-220 | B61: WELDING-CONSUM | C61: Welding consumables bulk | D61: Tools | E61: 8 | F61: T | G61: 4200 | K61: 30 | L61: 2026-07-30 | M61: M02 | N61: spec_missing
...

Sheet Suppliers
A1: VENDORS
A2: Suppliers — reference list (rows tagged 'test' are net-new)
A4: name | B4: category | C4: country | D4: lead_time_days | E4: on_time_delivery_pct | F4: quality_ppm | G4: annual_spend_usd | H4: approved_alternatives | I4: risk_flags | J4: Applies to tenants
A5: Helios Cast & Forge | B5: Forged valves | C5: India | D5: 42 | E5: 88 | F5: 1800 | G5: 740000 | H5: 0 | I5: single source; late NCR closure | J5: arcforge
A6: BluePeak Controls | B6: PLC and control panels | C6: Germany | D6: 55 | E6: 93 | F6: 650 | G6: 1280000 | H6: 1 | I6: port congestion | J6: arcforge,helios
A7: Copperline Metals | B7: Copper busbars | C7: Malaysia | D7: 28 | E7: 97 | F7: 300 | G7: 510000 | H7: 2 | J7: arcforge,helios
A8: Kerala Forge Works | B8: Forged valves | C8: India | D8: 56 | E8: 91 | F8: 1400 | G8: 180000 | H8: 1 | I8: capacity constrained | J8: arcforge
A9: Mitsuba Automation | B9: PLC and control panels | C9: Japan | D9: 62 | E9: 96 | F9: 420 | G9: 320000 | H9: 2 | J9: arcforge
A10: Delhi Metals Co | B10: Copper busbars | C10: India | D10: 24 | E10: 94 | F10: 520 | G10: 210000 | H10: 1 | I10: new supplier | J10: arcforge
A11: NorthCable Subsea | B11: Subsea cables | C11: Norway | D11: 180 | E11: 92 | F11: 410 | G11: 4200000 | H11: 1 | I11: weather window critical | J11: helios
A12: DeepDive ROV Systems | B12: ROV connectors | C12: UK | D12: 84 | E12: 89 | F12: 820 | G12: 860000 | H12: 0 | I12: single source; small batch | J12: helios
A13: Coastline Marine Coatings | B13: Marine epoxy | C13: Netherlands | D13: 35 | E13: 95 | F13: 280 | G13: 240000 | H13: 2 | J13: helios
A14: Aberdeen Steel Fab | B14: Offshore structural | C14: UK | D14: 140 | E14: 86 | F14: 1100 | G14: 2900000 | H14: 1 | I14: welder shortage | J14: helios
A15: Andritz Hydro | B15: Hydro turbines | C15: Austria | D15: 420 | E15: 94 | F15: 180 | G15: 6800000 | H15: 0 | I15: single source; long lead | J15: northwind
A16: ThyssenKrupp Specialty Plate | B16: Alloy plate | C16: Germany | D16: 110 | E16: 92 | F16: 320 | G16: 1500000 | H16: 2 | J16: northwind
A17: Bharat Heavy Electricals | B17: Generators | C17: India | D17: 300 | E17: 88 | F17: 520 | G17: 4100000 | H17: 1 | I17: capacity constrained | J17: northwind
A18: Voith Industrial Services | B18: Penstock fabrication | C18: Germany | D18: 240 | E18: 91 | F18: 410 | G18: 2200000 | H18: 1 | I18: transport over-dimensional | J18: northwind
A19: MeridianAlloys (test) | B19: Alloy plate | C19: India | D19: 90 | E19: 89 | F19: 720 | G19: 0 | H19: 2 | I19: new supplier | J19: arcforge,northwind
A20: ApexInstruments (test) | B20: Instrumentation | C20: USA | D20: 90 | E20: 95 | F20: 200 | G20: 0 | H20: 3 | J20: arcforge,helios,northwind
A21: StratoLogistics (test) | B21: Freight forwarding | C21: Singapore | D21: 14 | E21: 92 | F21: 0 | G21: 0 | H21: 5 | J21: arcforge,helios,northwind
A22: Trident Pumps (test) | B22: Rotating equipment | C22: China | D22: 150 | E22: 87 | F22: 980 | G22: 0 | H22: 2 | I22: trade tariffs | J22: arcforge,helios,northwind

Sheet Test Scenarios
A1: QA
A2: Test Scenarios — work P1 first, then P2/P3
A4: ID | B4: Feature area | C4: Persona | D4: Steps | E4: Expected outcome | F4: Priority | G4: Pass?
A5: T01 | B5: Auth · login | C5: any | D5: Open /login → pick any persona → land on /overview | E5: Redirected to /overview; topbar shows correct tenant + role | F5: P1
A6: T02 | B6: Auth · expired token | C6: arcforge-admin-01 | D6: Edit sessionStorage.sct.auth.token.v1 to invalid → reload | E6: Frontend clears token + redirects back to /login (no 'Token expired' wall) | F6: P1
A7: T03 | B7: Auth · cross-tenant 404 | C7: arcforge-buyer-01 | D7: GET /api/projects/HYD-MAHADEV-220 with arcforge token | E7: HTTP 404 (helios/northwind data not visible) | F7: P1
A8: T04 | B8: Portfolio · overview | C8: any-admin | D8: Open /overview | E8: Donut shows average completion %, spend rollup, buckets, schedule + activity panels | F8: P1
A9: T05 | B9: Portfolio · tenant differs | C9: all three admins | D9: Login each, compare /overview | E9: Each tenant shows distinct project counts, budgets, sectors | F9: P1
A10: T06 | B10: Portfolio · cache TTL | C10: arcforge-admin-01 | D10: Call /api/portfolio/summary twice within 10s, then after 15s | E10: Server-side cache returns same payload twice quickly, then refreshes | F10: P2
A11: T07 | B11: Command palette · open | C11: any | D11: Press ⌘K (Mac) or Ctrl+K (other) | E11: Modal opens centred; search input focused; lists default items | F11: P1
A12: T08 | B12: Command palette · search vendor | C12: arcforge-buyer-01 | D12: ⌘K → type 'helios' | E12: Helios Cast & Forge vendor row appears; Enter navigates to vendor page | F12: P1
A13: T09 | B13: Command palette · search BOM | C13: northwind-buyer-01 | D13: ⌘K → type 'runner' | E13: Francis runner BOM rows show; click navigates to project with bom=… | F13: P1
A14: T10 | B14: Projects · list + cards | C14: any | D14: Open /projects | E14: 4 cards per tenant; each shows completion bar + next milestone + In Xd; in-flight project ~55% (amber) | F14: P1
A15: T11 | B15: Projects · skeleton + animation | C15: any | D15: Hard reload /projects with throttled network (DevTools Slow 3G) | E15: Shimmer skeletons render first, then cards fade-up | F15: P2
A16: T12 | B16: Projects · hover prefetch | C16: any | D16: Hover a project card before clicking | E16: Detail page loads near-instant (prefetched JSON + Next route) | F16: P2
... A62: T58 | B62: CSV upload · cross-tenant denial | C62: arcforge-buyer-01 | D62: Try uploading bom-status-mix-PRJ-NW-STEEL.csv to PRJ-NW-STEEL with arcforge token | E62: Returns 404 (project_id appears 'unknown' from arcforge tenant's perspective) | F62: P1

Sheet Coverage Matrix
A1: MATRIX
A2: Feature coverage — counts by area (formula-driven)
A4: Area | B4: P1 count | C4: P2 count | D4: P3 count | E4: Total
A5: Agent chat | B5: =COUNTIFS('Test Scenarios'!B:B,A5&"*",'Test Scenarios'!F:F,"P1") -> 0 | C5: =COUNTIFS('Test Scenarios'!B:B,A5&"*",'Test Scenarios'!F:F,"P2") -> 1 | D5: =COUNTIFS('Test Scenarios'!B:B,A5&"*",'Test Scenarios'!F:F,"P3") -> 0 | E5: =SUM(B5:D5) -> 1
A6: Audit | B6: =COUNTIFS('Test Scenarios'!B:B,A6&"*",'Test Scenarios'!F:F,"P1") -> 1 | C6: =COUNTIFS('Test Scenarios'!B:B,A6&"*",'Test Scenarios'!F:F,"P2") -> 1 | D6: =COUNTIFS('Test Scenarios'!B:B,A6&"*",'Test Scenarios'!F:F,"P3") -> 0 | E6: =SUM(B6:D6) -> 2
A7: Auth | B7: =COUNTIFS('Test Scenarios'!B:B,A7&"*",'Test Scenarios'!F:F,"P1") -> 3 | C7: =COUNTIFS('Test Scenarios'!B:B,A7&"*",'Test Scenarios'!F:F,"P2") -> 0 | D7: =COUNTIFS('Test Scenarios'!B:B,A7&"*",'Test Scenarios'!F:F,"P3") -> 0 | E7: =SUM(B7:D7) -> 3
A8: Award | B8: =COUNTIFS('Test Scenarios'!B:B,A8&"*",'Test Scenarios'!F:F,"P1") -> 2 | C8: =COUNTIFS('Test Scenarios'!B:B,A8&"*",'Test Scenarios'!F:F,"P2") -> 0 | D8: =COUNTIFS('Test Scenarios'!B:B,A8&"*",'Test Scenarios'!F:F,"P3") -> 0 | E8: =SUM(B8:D8) -> 2
A9: BOM | B9: =COUNTIFS('Test Scenarios'!B:B,A9&"*",'Test Scenarios'!F:F,"P1") -> 3 | C9: =COUNTIFS('Test Scenarios'!B:B,A9&"*",'Test Scenarios'!F:F,"P2") -> 1 | D9: =COUNTIFS('Test Scenarios'!B:B,A9&"*",'Test Scenarios'!F:F,"P3") -> 0 | E9: =SUM(B9:D9) -> 4
A10: CSV upload | B10: =COUNTIFS('Test Scenarios'!B:B,A10&"*",'Test Scenarios'!F:F,"P1") -> 5 | C10: =COUNTIFS('Test Scenarios'!B:B,A10&"*",'Test Scenarios'!F:F,"P2") -> 3 | D10: =COUNTIFS('Test Scenarios'!B:B,A10&"*",'Test Scenarios'!F:F,"P3") -> 0 | E10: =SUM(B10:D10) -> 8
A11: Command palette | B11: =COUNTIFS('Test Scenarios'!B:B,A11&"*",'Test Scenarios'!F:F,"P1") -> 3 | C11: =COUNTIFS('Test Scenarios'!B:B,A11&"*",'Test Scenarios'!F:F,"P2") -> 0 | D11: =COUNTIFS('Test Scenarios'!B:B,A11&"*",'Test Scenarios'!F:F,"P3") -> 0 | E11: =SUM(B11:D11) -> 3
A12: Commercial | B12: =COUNTIFS('Test Scenarios'!B:B,A12&"*",'Test Scenarios'!F:F,"P1") -> 2 | C12: =COUNTIFS('Test Scenarios'!B:B,A12&"*",'Test Scenarios'!F:F,"P2") -> 0 | D12: =COUNTIFS('Test Scenarios'!B:B,A12&"*",'Test Scenarios'!F:F,"P3") -> 0 | E12: =SUM(B12:D12) -> 2
A13: Expediting | B13: =COUNTIFS('Test Scenarios'!B:B,A13&"*",'Test Scenarios'!F:F,"P1") -> 1 | C13: =COUNTIFS('Test Scenarios'!B:B,A13&"*",'Test Scenarios'!F:F,"P2") -> 1 | D13: =COUNTIFS('Test Scenarios'!B:B,A13&"*",'Test Scenarios'!F:F,"P3") -> 0 | E13: =SUM(B13:D13) -> 2
A14: Integrations | B14: =COUNTIFS('Test Scenarios'!B:B,A14&"*",'Test Scenarios'!F:F,"P1") -> 0 | C14: =COUNTIFS('Test Scenarios'!B:B,A14&"*",'Test Scenarios'!F:F,"P2") -> 0 | D14: =COUNTIFS('Test Scenarios'!B:B,A14&"*",'Test Scenarios'!F:F,"P3") -> 1 | E14: =SUM(B14:D14) -> 1
A15: Logistics | B15: =COUNTIFS('Test Scenarios'!B:B,A15&"*",'Test Scenarios'!F:F,"P1") -> 1 | C15: =COUNTIFS('Test Scenarios'!B:B,A15&"*",'Test Scenarios'!F:F,"P2") -> 2 | D15: =COUNTIFS('Test Scenarios'!B:B,A15&"*",'Test Scenarios'!F:F,"P3") -> 0 | E15: =SUM(B15:D15) -> 3
A16: PO | B16: =COUNTIFS('Test Scenarios'!B:B,A16&"*",'Test Scenarios'!F:F,"P1") -> 2 | C16: =COUNTIFS('Test Scenarios'!B:B,A16&"*",'Test Scenarios'!F:F,"P2") -> 2 | D16: =COUNTIFS('Test Scenarios'!B:B,A16&"*",'Test Scenarios'!F:F,"P3") -> 0 | E16: =SUM(B16:D16) -> 4
... A30: Weekly plan | B30: =COUNTIFS('Test Scenarios'!B:B,A30&"*",'Test Scenarios'!F:F,"P1") -> 1 | C30: =COUNTIFS('Test Scenarios'!B:B,A30&"*",'Test Scenarios'!F:F,"P2") -> 0 | D30: =COUNTIFS('Test Scenarios'!B:B,A30&"*",'Test Scenarios'!F:F,"P3") -> 0 | E30: =SUM(B30:D30) -> 1
A32: TOTAL | B32: =SUM(B5:B30) -> 37 | C32: =SUM(C5:C30) -> 28 | D32: =SUM(D5:D30) -> 2 | E32: =SUM(E5:E30) -> 67

Sheet Edge + Status CSVs
A1: EDGE CASES
A2: Auxiliary CSV files for robustness + completion testing
A4: File | B4: Purpose | C4: Target project | D4: Contents | E4: Expected behaviour
A5: bom-edge-malformed.csv | B5: Error-path probe | C5: any greenfield (e.g. PRJ-AF-CCGT) | D5: 12 rows, 6 deliberately bad | E5: rows_rejected count + per-row error messages
A6: bom-edge-minimal.csv | B6: Required-fields-only path | C6: any greenfield | D6: 5 rows, only code/description/quantity | E6: All accepted, uom defaults to EA, status = spec_missing
A7: bom-status-mix-PRJ-RB-660.csv | B7: Status-mix for Riverbank | C7: PRJ-RB-660 (arcforge) | D7: 9 rows: 5 delivered + 1 ordered + 3 planned | E7: Drives Riverbank to in-flight
A8: bom-status-mix-PRJ-HE-FPSO.csv | B8: Status-mix for Hawthorn FPSO | C8: PRJ-HE-FPSO (helios) | D8: 9 rows: 5 delivered + 1 ordered + 3 planned | E8: Drives FPSO to in-flight
A9: bom-status-mix-PRJ-NW-STEEL.csv | B9: Status-mix for Polaris Steel Mill | C9: PRJ-NW-STEEL (northwind) | D9: 9 rows: 5 delivered + 1 ordered + 3 planned | E9: Drives steel mill to in-flight
A11: HOW TO LOAD
A12: Sign in as a *-head-01 or *-admin-01 persona for the matching tenant. Open the target project → BOM tab → expand 'CSV format' → drop the file. The backend's upload_bom_csv now accepts an optional 'status' column (spec_missing | planned | requisitioned | ordered | delivered) and an optional 'parent_item_id' column — unknown statuses warn + fall back.

Sheet API Reference
A1: API
A2: Public endpoints — auth via Bearer JWT unless marked 'no'
A4: Method | B4: Endpoint | C4: Auth | D4: What it does | E4: Sample body
A5: POST | B5: /api/auth/login | C5: no | D5: Issue JWT for picked persona | E5: { "user_id": "arcforge-admin-01" }
A6: GET | B6: /api/auth/me | C6: yes | D6: Current user + permissions
A7: GET | B7: /api/auth/personas | C7: no | D7: All seeded personas across tenants
A8: GET | B8: /api/portfolio/summary | C8: yes | D8: Tenant cockpit aggregation (10s cache)
A9: GET | B9: /api/search/index | C9: yes | D9: Cmd+K palette index
A10: GET | B10: /api/projects | C10: yes | D10: List tenant projects
A11: GET | B11: /api/projects/progress | C11: yes | D11: Bulk completion % across projects
A12: GET | B12: /api/projects/{id} | C12: yes | D12: Project detail
A13: GET | B13: /api/projects/{id}/progress | C13: yes | D13: Single project completion breakdown
A14: GET | B14: /api/projects/{id}/bom | C14: yes | D14: BOM lines for project
A15: POST | B15: /api/projects/{id}/bom/upload | C15: yes | D15: Upload BOM CSV (multipart file)
A16: GET | B16: /api/projects/{id}/procurement-plan | C16: yes | D16: Build packages + long-lead + missing-spec flags
A17: POST | B17: /api/projects/{id}/bom/autofill | C17: yes | D17: AI fill missing supplier/category
... A19: GET | B19: /api/prs | C19: yes | D19: List PRs (tenant-scoped)
A20: POST | B20: /api/prs | C20: yes | D20: Create PR | E20: { project_id, bom_item_id, ... }
A21: GET | B21: /api/prs/{pr_no} | C21: yes | D21: PR detail
A22: GET | B22: /api/prs/{pr_no}/suggested-vendors | C22: yes | D22: Vendor suggestions for PR
A23: POST | B23: /api/prs/{pr_no}/submit-to-sap | C23: yes | D23: Submit to SAP CPI
A24: GET | B24: /api/rfqs | C24: yes | D24: List RFQs
A25: POST | B25: /api/rfqs | C25: yes | D25: Issue RFQ from PR | E25: { pr_no, vendors[], due_in_days, notes }
A26: GET | B26: /api/rfqs/{rfq_no}/quotes | C26: yes | D26: Quotes received
A27: POST | B27: /api/rfqs/{rfq_no}/quotes | C27: yes | D27: Receive quote | E27: { vendor, unit_price_usd, lead_time_days, ... }
A28: GET | B28: /api/rfqs/{rfq_no}/compare | C28: yes | D28: Quote comparison + winner
A29: POST | B29: /api/rfqs/{rfq_no}/award | C29: yes | D29: Award RFQ + draft PO | E29: { quote_id, rationale? }
A30: GET | B30: /api/sourcing-pos | C30: yes | D30: List sourcing POs
A31: GET | B31: /api/sourcing-pos/{po_no}/timeline | C31: yes | D31: Full audit chain for PO
A32: POST | B32: /api/sourcing-pos/{po_no}/submit-to-sap | C32: yes | D32: Submit PO to SAP CPI
A33: GET | B33: /api/vendors/intel | C33: yes | D33: Vendor scorecard list
A34: GET | B34: /api/vendors/intel/{name} | C34: yes | D34: Single scorecard + alternates
A35: GET | B35: /api/vendors/intel/{name}/briefing | C35: yes | D35: AI risk briefing (Grok or deterministic)
A36: GET | B36: /api/vendors/concentration | C36: yes | D36: Category concentration
A37: GET | B37: /api/expediting/queue | C37: yes | D37: Expedite queue with urgency
A38: POST | B38: /api/expediting/{po}/draft-followup | C38: yes | D38: AI draft tone-aware follow-up email
A39: GET | B39: /api/logistics/shipments | C39: yes | D39: Shipment list
A40: POST | B40: /api/logistics/shipments/{po}/events | C40: yes | D40: Add shipment event
A41: GET | B41: /api/commercial/summary | C41: yes | D41: Budget vs quoted vs awarded roll-up
... A43: GET | B43: /api/weekly-plan | C43: yes | D43: Weekly priority plan + AI narrative
...
